<mujoco model="MuJoCo Model">
  <compiler angle="radian"/>
  <extension>
    <plugin plugin="mujoco.elasticity.cable">
      <instance name="compositewire0:">
        <config key="twist" value="1e7"/>
        <config key="bend" value="4e6"/>
        <config key="vmax" value="0.05"/>
      </instance>
    </plugin>
  </extension>
  <custom>
    <text name="composite_wire0:" data="rope_wire0:"/>
  </custom>
  <worldbody>
    <body name="wall" pos="0 -1 0">
      <geom size="1 0.1 1" pos="0 0 1" type="box" rgba="0.8 0.6 0.4 1"/>
      <body name="attachment_points" pos="-0.3 0.1 1.25">
        <body name="attachment_point_1">
          <geom size="0.03" rgba="1 0 0 1"/>
          <body name="wire0:B_first" pos="0 0 0" quat="0 0.735724 0.677282 0">
            <geom name="wire0:G0" size="0.01 0.0206448" pos="0.0206448 0 0" quat="0.707107 0 -0.707107 0" type="capsule" condim="1" friction="0.7" rgba="1 0 0 1"/>
            <site name="wire0:S_first" pos="0 0 0" group="3"/>
            <plugin instance="compositewire0:"/>
            <body name="wire0:B_1" pos="0.0412897 0 0" quat="0.996584 0 0 0.0825793">
              <joint name="wire0:J_1" pos="0 0 0" type="ball" group="3" actuatorfrclimited="false" damping="1"/>
              <geom name="wire0:G1" size="0.01 0.0206448" pos="0.0206448 0 0" quat="0.707107 0 -0.707107 0" type="capsule" condim="1" friction="0.7" rgba="1 0 0 1"/>
              <plugin instance="compositewire0:"/>
              <body name="wire0:B_2" pos="0.0412897 0 0" quat="0.996584 0 0 0.0825793">
                <joint name="wire0:J_2" pos="0 0 0" type="ball" group="3" actuatorfrclimited="false" damping="1"/>
                <geom name="wire0:G2" size="0.01 0.0206448" pos="0.0206448 0 0" quat="0.707107 0 -0.707107 0" type="capsule" condim="1" friction="0.7" rgba="1 0 0 1"/>
                <plugin instance="compositewire0:"/>
                <body name="wire0:B_3" pos="0.0412897 0 0" quat="0.996584 0 0 0.0825794">
                  <joint name="wire0:J_3" pos="0 0 0" type="ball" group="3" actuatorfrclimited="false" damping="1"/>
                  <geom name="wire0:G3" size="0.01 0.0206448" pos="0.0206448 0 0" quat="0.707107 0 -0.707107 0" type="capsule" condim="1" friction="0.7" rgba="1 0 0 1"/>
                  <plugin instance="compositewire0:"/>
                  <body name="wire0:B_4" pos="0.0412897 0 0" quat="0.996584 0 0 0.0825793">
                    <joint name="wire0:J_4" pos="0 0 0" type="ball" group="3" actuatorfrclimited="false" damping="1"/>
                    <geom name="wire0:G4" size="0.01 0.0206448" pos="0.0206448 0 0" quat="0.707107 0 -0.707107 0" type="capsule" condim="1" friction="0.7" rgba="1 0 0 1"/>
                    <plugin instance="compositewire0:"/>
                    <body name="wire0:B_5" pos="0.0412897 0 0" quat="0.996584 0 0 0.0825793">
                      <joint name="wire0:J_5" pos="0 0 0" type="ball" group="3" actuatorfrclimited="false" damping="1"/>
                      <geom name="wire0:G5" size="0.01 0.0206448" pos="0.0206448 0 0" quat="0.707107 0 -0.707107 0" type="capsule" condim="1" friction="0.7" rgba="1 0 0 1"/>
                      <plugin instance="compositewire0:"/>
                      <body name="wire0:B_6" pos="0.0412897 0 0" quat="0.996584 0 0 0.0825794">
                        <joint name="wire0:J_6" pos="0 0 0" type="ball" group="3" actuatorfrclimited="false" damping="1"/>
                        <geom name="wire0:G6" size="0.01 0.0206448" pos="0.0206448 0 0" quat="0.707107 0 -0.707107 0" type="capsule" condim="1" friction="0.7" rgba="1 0 0 1"/>
                        <plugin instance="compositewire0:"/>
                        <body name="wire0:B_7" pos="0.0412897 0 0" quat="0.996584 0 0 0.0825793">
                          <joint name="wire0:J_7" pos="0 0 0" type="ball" group="3" actuatorfrclimited="false" damping="1"/>
                          <geom name="wire0:G7" size="0.01 0.0206448" pos="0.0206448 0 0" quat="0.707107 0 -0.707107 0" type="capsule" condim="1" friction="0.7" rgba="1 0 0 1"/>
                          <plugin instance="compositewire0:"/>
                          <body name="wire0:B_8" pos="0.0412897 0 0" quat="0.996584 0 0 0.0825795">
                            <joint name="wire0:J_8" pos="0 0 0" type="ball" group="3" actuatorfrclimited="false" damping="1"/>
                            <geom name="wire0:G8" size="0.01 0.0206448" pos="0.0206448 0 0" quat="0.707107 0 -0.707107 0" type="capsule" condim="1" friction="0.7" rgba="1 0 0 1"/>
                            <plugin instance="compositewire0:"/>
                            <body name="wire0:B_9" pos="0.0412897 0 0" quat="0.996585 0 0 0.0825792">
                              <joint name="wire0:J_9" pos="0 0 0" type="ball" group="3" actuatorfrclimited="false" damping="1"/>
                              <geom name="wire0:G9" size="0.01 0.0206448" pos="0.0206448 0 0" quat="0.707107 0 -0.707107 0" type="capsule" condim="1" friction="0.7" rgba="1 0 0 1"/>
                              <plugin instance="compositewire0:"/>
                              <body name="wire0:B_10" pos="0.0412897 0 0" quat="0.996585 0 0 0.0825792">
                                <joint name="wire0:J_10" pos="0 0 0" type="ball" group="3" actuatorfrclimited="false" damping="1"/>
                                <geom name="wire0:G10" size="0.01 0.0206448" pos="0.0206448 0 0" quat="0.707107 0 -0.707107 0" type="capsule" condim="1" friction="0.7" rgba="1 0 0 1"/>
                                <plugin instance="compositewire0:"/>
                                <body name="wire0:B_11" pos="0.0412897 0 0" quat="0.996584 0 0 0.0825796">
                                  <joint name="wire0:J_11" pos="0 0 0" type="ball" group="3" actuatorfrclimited="false" damping="1"/>
                                  <geom name="wire0:G11" size="0.01 0.0206448" pos="0.0206448 0 0" quat="0.707107 0 -0.707107 0" type="capsule" condim="1" friction="0.7" rgba="1 0 0 1"/>
                                  <plugin instance="compositewire0:"/>
                                  <body name="wire0:B_12" pos="0.0412896 0 0" quat="0.996585 0 0 0.0825791">
                                    <joint name="wire0:J_12" pos="0 0 0" type="ball" group="3" actuatorfrclimited="false" damping="1"/>
                                    <geom name="wire0:G12" size="0.01 0.0206448" pos="0.0206448 0 0" quat="0.707107 0 -0.707107 0" type="capsule" condim="1" friction="0.7" rgba="1 0 0 1"/>
                                    <plugin instance="compositewire0:"/>
                                    <body name="wire0:B_13" pos="0.0412897 0 0" quat="0.996584 0 0 0.0825795">
                                      <joint name="wire0:J_13" pos="0 0 0" type="ball" group="3" actuatorfrclimited="false" damping="1"/>
                                      <geom name="wire0:G13" size="0.01 0.0206448" pos="0.0206448 0 0" quat="0.707107 0 -0.707107 0" type="capsule" condim="1" friction="0.7" rgba="1 0 0 1"/>
                                      <plugin instance="compositewire0:"/>
                                      <body name="wire0:B_14" pos="0.0412897 0 0" quat="0.996584 0 0 0.0825796">
                                        <joint name="wire0:J_14" pos="0 0 0" type="ball" group="3" actuatorfrclimited="false" damping="1"/>
                                        <geom name="wire0:G14" size="0.01 0.0206448" pos="0.0206448 0 0" quat="0.707107 0 -0.707107 0" type="capsule" condim="1" friction="0.7" rgba="1 0.604668 0 1"/>
                                        <plugin instance="compositewire0:"/>
                                        <body name="wire0:B_15" pos="0.0412897 0 0" quat="0.996585 0 0 0.0825788">
                                          <joint name="wire0:J_15" pos="0 0 0" type="ball" group="3" actuatorfrclimited="false" damping="1"/>
                                          <geom name="wire0:G15" size="0.01 0.0206448" pos="0.0206448 0 0" quat="0.707107 0 -0.707107 0" type="capsule" condim="1" friction="0.7" rgba="0.307308 1 0 1"/>
                                          <plugin instance="compositewire0:"/>
                                          <body name="wire0:B_16" pos="0.0412897 0 0" quat="0.996584 0 0 0.0825798">
                                            <joint name="wire0:J_16" pos="0 0 0" type="ball" group="3" actuatorfrclimited="false" damping="1"/>
                                            <geom name="wire0:G16" size="0.01 0.0206448" pos="0.0206448 0 0" quat="0.707107 0 -0.707107 0" type="capsule" condim="1" friction="0.7" rgba="0 1 0.678544 1"/>
                                            <plugin instance="compositewire0:"/>
                                            <body name="wire0:B_17" pos="0.0412897 0 0" quat="0.996585 0 0 0.0825793">
                                              <joint name="wire0:J_17" pos="0 0 0" type="ball" group="3" actuatorfrclimited="false" damping="1"/>
                                              <geom name="wire0:G17" size="0.01 0.0206448" pos="0.0206448 0 0" quat="0.707107 0 -0.707107 0" type="capsule" condim="1" friction="0.7" rgba="0 0.551422 1 1"/>
                                              <plugin instance="compositewire0:"/>
                                              <body name="wire0:B_last" pos="0.0412897 0 0" quat="0.996585 0 0 0.0825792">
                                                <joint name="wire0:J_last" pos="0 0 0" type="ball" group="3" actuatorfrclimited="false" damping="1"/>
                                                <geom name="wire0:G18" size="0.01 0.0206448" pos="0.0206448 0 0" quat="0.707107 0 -0.707107 0" type="capsule" condim="1" friction="0.7" rgba="0 0.235536 1 1"/>
                                                <site name="wire0:S_last" pos="0.0412897 0 0" group="3"/>
                                                <plugin instance="compositewire0:"/>
                                              </body>
                                            </body>
                                          </body>
                                        </body>
                                      </body>
                                    </body>
                                  </body>
                                </body>
                              </body>
                            </body>
                          </body>
                        </body>
                      </body>
                    </body>
                  </body>
                </body>
              </body>
            </body>
          </body>
        </body>
        <body name="attachment_point_2" pos="0.5 0 0">
          <geom size="0.03" rgba="0 1 0 1"/>
        </body>
      </body>
    </body>
  </worldbody>
  <contact>
    <exclude body1="wire0:B_first" body2="wire0:B_1"/>
    <exclude body1="wire0:B_1" body2="wire0:B_2"/>
    <exclude body1="wire0:B_2" body2="wire0:B_3"/>
    <exclude body1="wire0:B_3" body2="wire0:B_4"/>
    <exclude body1="wire0:B_4" body2="wire0:B_5"/>
    <exclude body1="wire0:B_5" body2="wire0:B_6"/>
    <exclude body1="wire0:B_6" body2="wire0:B_7"/>
    <exclude body1="wire0:B_7" body2="wire0:B_8"/>
    <exclude body1="wire0:B_8" body2="wire0:B_9"/>
    <exclude body1="wire0:B_9" body2="wire0:B_10"/>
    <exclude body1="wire0:B_10" body2="wire0:B_11"/>
    <exclude body1="wire0:B_11" body2="wire0:B_12"/>
    <exclude body1="wire0:B_12" body2="wire0:B_13"/>
    <exclude body1="wire0:B_13" body2="wire0:B_14"/>
    <exclude body1="wire0:B_14" body2="wire0:B_15"/>
    <exclude body1="wire0:B_15" body2="wire0:B_16"/>
    <exclude body1="wire0:B_16" body2="wire0:B_17"/>
    <exclude body1="wire0:B_17" body2="wire0:B_last"/>
    <exclude body1="wire0:B_last" body2="attachment_point_2"/>
  </contact>
</mujoco>
